Workbook

Sheet Sales by Customer Detail
A1: First Arriving LLC
A2: Sales by Customer Detail
A3: January 2018 - April 2022
B5: Customer | C5: Date | D5: Transaction Type | E5: Num | F5: Product/Service | G5: Memo/Description | H5: Account | I5: Class | J5: Qty | K5: Sales Price | L5: Amount | M5: Balance | N5: Subscription Start Date | O5: Subscription End Date
B6: Maryland State Fireman's Assoc | C6: 01/02/2018 | D6: Invoice | E6: 1014 | F6: Strategic Services:Strategic Services | G6: Maryland State Fireman's Association - Recruitment Campaign Marketing Services (January Payment) | H6: 4307 Marketing Services:Marketing Strategy/Ops | J6: 1 | K6: 30000 | L6: 30000 | M6: 30000
B7: National Fallen Firefighters Foundation (MD) | C7: 01/03/2018 | D7: Invoice | E7: 1016 | F7: Website Packages:Hosting & Support:Hosting & Support | G7: September 2017-December 2017 | H7: 4902 Websites:Website Hosting/Support | J7: 4 | K7: 150 | L7: 600 | M7: 30600
B8: APS Firehouse Alerting | C8: 01/03/2018 | D8: Invoice | E8: 1017 | F8: Website Packages:Hosting & Support:Hosting & Support | G8: 10% Annual Discount | H8: 4902 Websites:Website Hosting/Support | J8: 1 | K8: -35 | L8: -35 | M8: 30565
B9: APS Firehouse Alerting | C9: 01/03/2018 | D9: Invoice | E9: 1017 | F9: Website Packages:Hosting & Support:Hosting & Support | G9: 2018 Hosting & Support | H9: 4902 Websites:Website Hosting/Support | J9: 12 | K9: 29 | L9: 348 | M9: 30913
B10: First Class (NC) Emergency Vehicles | C10: 01/03/2018 | D10: Invoice | E10: 1018 | F10: Website Packages:Hosting & Support:Hosting & Support | G10: Hosting & Support for 2018 | H10: 4902 Websites:Website Hosting/Support | J10: 12 | K10: 49 | L10: 588 | M10: 31501
B11: National Fallen Firefighters Foundation (MD) | C11: 01/03/2018 | D11: Invoice | E11: 1016 | F11: Website Packages:Hosting & Support:Hosting & Support | G11: 2018 | H11: 4902 Websites:Website Hosting/Support | J11: 12 | K11: 150 | L11: 1800 | M11: 33301
B12: First Class (NC) Emergency Vehicles | C12: 01/03/2018 | D12: Invoice | E12: 1018 | F12: Website Packages:Hosting & Support:Hosting & Support | G12: Annual Pre-Pay Discount | H12: 4902 Websites:Website Hosting/Support | J12: 1 | K12: -58.8 | L12: -58.8 | M12: 33242.2
B13: National Fallen Firefighters Foundation (MD) | C13: 01/03/2018 | D13: Invoice | E13: 1016 | F13: Website Packages:Hosting & Support:Hosting & Support | G13: 10% Courtesy Discount | H13: 4902 Websites:Website Hosting/Support | J13: 1 | K13: -240 | L13: -240 | M13: 33002.2
B14: South Carolina State Firefighters Association:South Carolina State Firefighter's Association - Recruitment | C14: 01/18/2018 | D14: Invoice | E14: 1019 | F14: Recruitment Services:Recruitment & Retention Strategy & Project Management | G14: SCSFA Recruitment Marketing - Initial Retainer | H14: 4603 Recruitment Services:Recruitment Strategy/Management | J14: 1 | K14: 40000 | L14: 40000 | M14: 73002.2
B15: Bendersville Community (PA) Fire Company | C15: 01/31/2018 | D15: Invoice | E15: 1020 | F15: Website Packages:Hosting & Support:Hosting & Support | G15: Hosting & Support (Package 2 Level) - 2 Years Site Post Launch Date | H15: 4902 Websites:Website Hosting/Support | J15: 24 | K15: 59 | L15: 1416 | M15: 74418.2
B16: Bendersville Community (PA) Fire Company | C16: 01/31/2018 | D16: Invoice | E16: 1020 | F16: Web Services:Website Services | G16: Package 2 - Custom | H16: 4903 Websites:Website Services | J16: 1 | K16: 3495 | L16: 3495 | M16: 77913.2
B17: Round Lake (NY) Hose Company #1 Inc | C17: 01/31/2018 | D17: Invoice | E17: 1021 | F17: Web Services:Website Services | G17: Package 1 + Enhanced Recruitment/Fundraising, QGiv Basic Plan (initially), Review Print Mailer, Custom FB Audiences, 501c3 Setup for Google and Facebook | H17: 4903 Websites:Website Services | J17: 1 | K17: 0 | L17: 0 | M17: 77913.2
B18: Round Lake (NY) Hose Company #1 Inc | C18: 01/31/2018 | D18: Invoice | E18: 1021 | F18: Web Services:Website Services | G18: Package 2 - Custom (Defined Below) | H18: 4903 Websites:Website Services | J18: 1 | K18: 2795 | L18: 2795 | M18: 80708.2
B19: Bendersville Community (PA) Fire Company | C19: 01/31/2018 | D19: Invoice | E19: 1020 | F19: Strategic Services:Strategic Services | G19: Facebook Marketing Pass Through (Two Years) | H19: 4307 Marketing Services:Marketing Strategy/Ops | J19: 1 | K19: 600 | L19: 600 | M19: 81308.2
B20: Bendersville Community (PA) Fire Company | C20: 01/31/2018 | D20: Invoice | E20: 1020 | F20: Strategic Services:Strategic Services | G20: NVFC Member / Courtesy Discount | H20: 4307 Marketing Services:Marketing Strategy/Ops | J20: 1 | K20: -511 | L20: -511 | M20: 80797.2
B21: South Carolina State Firefighters Association:South Carolina State Firefighter's Association - Recruitment | C21: 02/02/2018 | D21: Invoice | E21: 1022 | F21: Strategic Services:Strategic Services | G21: SCSFA Recruitment Marketing Program - February 15 Installment | H21: 4307 Marketing Services:Marketing Strategy/Ops | J21: 1 | K21: 30000 | L21: 30000 | M21: 110797.2
B22: Maryland State Fireman's Assoc | C22: 02/02/2018 | D22: Invoice | E22: 1015 | F22: Strategic Services:Strategic Services | G22: UPDATED - Maryland State Fireman's Association - Recruitment Campaign Marketing Services - February Invoice | H22: 4307 Marketing Services:Marketing Strategy/Ops | J22: 1 | K22: 30000 | L22: 30000 | M22: 140797.2
B23: Providence (MD) Volunteer Fire Co. | C23: 02/20/2018 | D23: Invoice | E23: 1024 | F23: Strategic Services:Strategic Services | G23: Payments on Future Invoices (See Notes Below) | H23: 4307 Marketing Services:Marketing Strategy/Ops | J23: 1 | K23: -2830 | L23: -2830 | M23: 137967.2
... B138: Colmar (PA) Volunteer Fire Co:Colmar (PA) Recruitment | C138: 08/13/2018 | D138: Invoice | E138: 1075 | F138: Website Packages:Hosting & Support:Hosting & Support | G138: First 12 months of Website hosting/support included free, then $59/month, due annually on anniversary date of launch | H138: 4902 Websites:Website Hosting/Support | J138: 1 | K138: 0 | L138: 0 | M138: 458485.02
B139: North Carolina (NC) Fire and Rescue Administrative Professionals, Inc | C139: 08/13/2018 | D139: Invoice | E139: 1074 | F139: Website Packages:Hosting & Support:Hosting & Support | G139: First 12 months of hosting/support included from launch date per Proposal., then $29/month paid annually due on anniversary date of launch. | H139: 4902 Websites:Website Hosting/Support | K139: 0 | L139: 0 | M139: 458485.02
B140: Glacier Park International Airport (MT) Fire Rescue | C140: 08/13/2018 | D140: Invoice | E140: 1076 | F140: Dashboards:Dashboard STANDARD Setup | G140: Pre-Loaded PSIN Chromebit (includes shipping) | H140: 4130 Digital Signage:Dashboard Setup Fees | J140: 1 | K140: 119 | L140: 119 | M140: 458604.02
B141: Praetorian Digital (CA) | C141: 08/16/2018 | D141: Invoice | E141: 1078 | F141: Marketing Services:Marketing Services - Sagetopia (deleted) | G141: Project Includes - Design & Layout - Hyperlinks - Text changes - File preparation for printing | H141: 4304 Marketing Services:Design/Production - Third Party Pass Through | J141: 1 | K141: 0 | L141: 0 | M141: 458604.02
B142: Praetorian Digital (CA) | C142: 08/16/2018 | D142: Invoice | E142: 1078 | F142: Marketing Services:Marketing Services - Sagetopia (deleted) | G142: Stock Images - Female Police Officer | H142: 4304 Marketing Services:Design/Production - Third Party Pass Through | J142: 1 | K142: 12 | L142: 12 | M142: 458616.02
B143: Praetorian Digital (CA) | C143: 08/16/2018 | D143: Invoice | E143: 1077 | F143: Marketing Services:Marketing Services - Sagetopia (deleted) | G143: eBook: Increase Safety and Maximize Resources with Connected Devices and Cloud-based Technology | H143: 4304 Marketing Services:Design/Production - Third Party Pass Through | J143: 1 | K143: 0 | L143: 0 | M143: 458616.02
B144: Praetorian Digital (CA) | C144: 08/16/2018 | D144: Invoice | E144: 1077 | F144: Marketing Services:Marketing Services - Sagetopia (deleted) | G144: eBook Design & Layout (16 pages) - 2 Cover Options - Interior Page Layout - 3 rounds of text edits - Not to exceed 4 hours of text edits - Hyperlinks (TOC, email & web addresses) - Capped at $1750 | H144: 4304 Marketing Services:Design/Production - Third Party Pass Through | J144: 1 | K144: 1750 | L144: 1750 | M144: 460366.02
B145: Praetorian Digital (CA) | C145: 08/16/2018 | D145: Invoice | E145: 1078 | F145: Marketing Services:Marketing Services - Sagetopia (deleted) | G145: Design: Interior Pages | H145: 4304 Marketing Services:Design/Production - Third Party Pass Through | J145: 6 | K145: 175 | L145: 1050 | M145: 461416.02
B146: Praetorian Digital (CA) | C146: 08/16/2018 | D146: Invoice | E146: 1078 | F146: Marketing Services:Marketing Services - Sagetopia (deleted) | G146: Design: Covers | H146: 4304 Marketing Services:Design/Production - Third Party Pass Through | J146: 1 | K146: 300 | L146: 300 | M146: 461716.02
B147: Praetorian Digital (CA) | C147: 08/16/2018 | D147: Invoice | E147: 1078 | F147: Marketing Services:Marketing Services - Sagetopia (deleted) | G147: eBook Design: Kronos / PoliceOne Increase Engagement with Modern Scheduling Technology Total: 7 Pages | H147: 4304 Marketing Services:Design/Production - Third Party Pass Through | J147: 1 | K147: 0 | L147: 0 | M147: 461716.02
B148: Praetorian Digital (CA) | C148: 08/16/2018 | D148: Invoice | E148: 1079 | F148: Marketing Services:Marketing Services - Sagetopia (deleted) | G148: Project Includes - Design & Layout - Hyperlinks - Text changes - File preparation for printing | H148: 4304 Marketing Services:Design/Production - Third Party Pass Through | J148: 1 | K148: 0 | L148: 0 | M148: 461716.02
B149: Praetorian Digital (CA) | C149: 08/16/2018 | D149: Invoice | E149: 1079 | F149: Marketing Services:Marketing Services - Sagetopia (deleted) | G149: Design: Interior Pages | H149: 4304 Marketing Services:Design/Production - Third Party Pass Through | J149: 11 | K149: 175 | L149: 1925 | M149: 463641.02
B150: Praetorian Digital (CA) | C150: 08/16/2018 | D150: Invoice | E150: 1079 | F150: Marketing Services:Marketing Services - Sagetopia (deleted) | G150: Design: Covers | H150: 4304 Marketing Services:Design/Production - Third Party Pass Through | J150: 1 | K150: 300 | L150: 300 | M150: 463941.02
B151: Praetorian Digital (CA) | C151: 08/16/2018 | D151: Invoice | E151: 1079 | F151: Marketing Services:Marketing Services - Sagetopia (deleted) | G151: eBook Design: Kyocera / PoliceOne What Agencies need to know about: BWC-ENABLED SMARTPHONES Total: 12 Pages | H151: 4304 Marketing Services:Design/Production - Third Party Pass Through | J151: 1 | K151: 0 | L151: 0 | M151: 463941.02
... B429: Interstate Rescue (VA) | C429: 01/01/2019 | D429: Invoice | E429: 1233 | F429: Strategic Services:Strategic Services | G429: Regional Marketing Program - Setup per proposal 12/26 | H429: 4307 Marketing Services:Marketing Strategy/Ops | J429: 1 | K429: 1000 | L429: 1000 | M429: 1178294.6
B430: Branchville (MD) Volunteer Fire Company and Rescue Squad, Inc | C430: 01/02/2019 | D430: Invoice | E430: 1234 | F430: Dashboards:Dashboard - Hardware (deleted) | G430: Chromebit for additional dashboard | H430: 4700 Strategic Services | J430: 0 | L430: 0 | M430: 1178294.6
B431: Haltom City (TX) Fire Department | C431: 01/03/2019 | D431: Invoice | E431: 1235 | F431: Dashboards:Dashboard STANDARD Setup | G431: PSIN Implementation Fee for 3 locations | H431: 4130 Digital Signage:Dashboard Setup Fees | J431: 1 | K431: 795 | L431: 795 | M431: 1179089.6
B432: Haltom City (TX) Fire Department | C432: 01/03/2019 | D432: Invoice | E432: 1235 | F432: Dashboards:Dashboard - First Year New Standard License (LEGACY) (deleted) | G432: Annual Licenses for PSIN Service (renews annually due on anniversary of deployment) | H432: 4110 Digital Signage:Dashboard Licenses | J432: 4 | K432: 349 | L432: 1396 | M432: 1180485.6
...

Sheet Anonymizer
A2: Customer from QB | B2: Customer | D2: Product/Service per QB | E2: Product/Service | F2: Dashboard Subscription | G2: Set Up | H2: Hardware | I2: Website Hosting / Support Subscription? | J2: Website Professional Services | K2: LLC Item
A3: {=_xlfn._xlws.SORT(_xlfn.UNIQUE('Sales by Customer Detail'!B6:B5761))} -> ​Cochran (PA) Hose Fire Department | B3: Customer 1 | D3: {=_xlfn._xlws.SORT(_xlfn.UNIQUE('Sales by Customer Detail'!F6:F5761))} -> Central County MO Fire Rescue - 1 Additional License - 042020 (deleted) | E3: Prod/Svc1 | F3: =IF(VLOOKUP(D3,[1]List!$A$3:$G$100,2,FALSE)=0,"",VLOOKUP(D3,[1]List!$A$3:$G$100,2,FALSE)) -> yes | G3: =IF(VLOOKUP(D3,[1]List!$A$3:$G$100,3,FALSE)=0,"",VLOOKUP(D3,[1]List!$A$3:$G$100,3,FALSE)) | H3: =IF(VLOOKUP(D3,[1]List!$A$3:$G$100,4,FALSE)=0,"",VLOOKUP(D3,[1]List!$A$3:$G$100,4,FALSE)) | I3: =IF(VLOOKUP(D3,[1]List!$A$3:$G$100,5,FALSE)=0,"",VLOOKUP(D3,[1]List!$A$3:$G$100,5,FALSE)) | J3: =IF(VLOOKUP(D3,[1]List!$A$3:$G$100,6,FALSE)=0,"",VLOOKUP(D3,[1]List!$A$3:$G$100,6,FALSE)) | K3: =IF(VLOOKUP(D3,[1]List!$A$3:$G$100,7,FALSE)=0,"",VLOOKUP(D3,[1]List!$A$3:$G$100,7,FALSE))
A4: ​Cochran (PA) Hose Fire Department:Cochran (PA) Hose Fire Department -Enhanced Website Package-FY22-March | B4: Customer 2 | D4: Coaldale & District Emergency Services - 1 Dashboard - 042220 (deleted) | E4: Prod/Svc2 | F4: =IF(VLOOKUP(D4,[1]List!$A$3:$G$100,2,FALSE)=0,"",VLOOKUP(D4,[1]List!$A$3:$G$100,2,FALSE)) -> yes | G4: =IF(VLOOKUP(D4,[1]List!$A$3:$G$100,3,FALSE)=0,"",VLOOKUP(D4,[1]List!$A$3:$G$100,3,FALSE)) | H4: =IF(VLOOKUP(D4,[1]List!$A$3:$G$100,4,FALSE)=0,"",VLOOKUP(D4,[1]List!$A$3:$G$100,4,FALSE)) | I4: =IF(VLOOKUP(D4,[1]List!$A$3:$G$100,5,FALSE)=0,"",VLOOKUP(D4,[1]List!$A$3:$G$100,5,FALSE)) | J4: =IF(VLOOKUP(D4,[1]List!$A$3:$G$100,6,FALSE)=0,"",VLOOKUP(D4,[1]List!$A$3:$G$100,6,FALSE)) | K4: =IF(VLOOKUP(D4,[1]List!$A$3:$G$100,7,FALSE)=0,"",VLOOKUP(D4,[1]List!$A$3:$G$100,7,FALSE))
A5: ​Genesee County (NY) Emergency Management Services:​Batavia (NY) Fire Department, Town of (Genesee County) | B5: Customer 3 | D5: Consulting Services - Fire/EMS Departments | E5: Prod/Svc3 | F5: =IF(VLOOKUP(D5,[1]List!$A$3:$G$100,2,FALSE)=0,"",VLOOKUP(D5,[1]List!$A$3:$G$100,2,FALSE)) | G5: =IF(VLOOKUP(D5,[1]List!$A$3:$G$100,3,FALSE)=0,"",VLOOKUP(D5,[1]List!$A$3:$G$100,3,FALSE)) | H5: =IF(VLOOKUP(D5,[1]List!$A$3:$G$100,4,FALSE)=0,"",VLOOKUP(D5,[1]List!$A$3:$G$100,4,FALSE)) | I5: =IF(VLOOKUP(D5,[1]List!$A$3:$G$100,5,FALSE)=0,"",VLOOKUP(D5,[1]List!$A$3:$G$100,5,FALSE)) | J5: =IF(VLOOKUP(D5,[1]List!$A$3:$G$100,6,FALSE)=0,"",VLOOKUP(D5,[1]List!$A$3:$G$100,6,FALSE)) | K5: =IF(VLOOKUP(D5,[1]List!$A$3:$G$100,7,FALSE)=0,"",VLOOKUP(D5,[1]List!$A$3:$G$100,7,FALSE)) -> yes
A6: ​Genesee County (NY) Emergency Management Services:​Elba (NY) Volunteer Fire Department (Genesee County) | B6: Customer 4 | D6: Customer Referral Discount | E6: Prod/Svc4 | F6: =IF(VLOOKUP(D6,[1]List!$A$3:$G$100,2,FALSE)=0,"",VLOOKUP(D6,[1]List!$A$3:$G$100,2,FALSE)) | G6: =IF(VLOOKUP(D6,[1]List!$A$3:$G$100,3,FALSE)=0,"",VLOOKUP(D6,[1]List!$A$3:$G$100,3,FALSE)) | H6: =IF(VLOOKUP(D6,[1]List!$A$3:$G$100,4,FALSE)=0,"",VLOOKUP(D6,[1]List!$A$3:$G$100,4,FALSE)) | I6: =IF(VLOOKUP(D6,[1]List!$A$3:$G$100,5,FALSE)=0,"",VLOOKUP(D6,[1]List!$A$3:$G$100,5,FALSE)) | J6: =IF(VLOOKUP(D6,[1]List!$A$3:$G$100,6,FALSE)=0,"",VLOOKUP(D6,[1]List!$A$3:$G$100,6,FALSE)) | K6: =IF(VLOOKUP(D6,[1]List!$A$3:$G$100,7,FALSE)=0,"",VLOOKUP(D6,[1]List!$A$3:$G$100,7,FALSE)) -> yes
A7: ​Genesee County (NY) Emergency Management Services:​LeRoy (NY) Fire Department (Genesee County) | B7: Customer 5 | D7: Dashboard BASIC Setup | E7: Prod/Svc5 | F7: =IF(VLOOKUP(D7,[1]List!$A$3:$G$100,2,FALSE)=0,"",VLOOKUP(D7,[1]List!$A$3:$G$100,2,FALSE)) | G7: =IF(VLOOKUP(D7,[1]List!$A$3:$G$100,3,FALSE)=0,"",VLOOKUP(D7,[1]List!$A$3:$G$100,3,FALSE)) -> yes | H7: =IF(VLOOKUP(D7,[1]List!$A$3:$G$100,4,FALSE)=0,"",VLOOKUP(D7,[1]List!$A$3:$G$100,4,FALSE)) | I7: =IF(VLOOKUP(D7,[1]List!$A$3:$G$100,5,FALSE)=0,"",VLOOKUP(D7,[1]List!$A$3:$G$100,5,FALSE)) | J7: =IF(VLOOKUP(D7,[1]List!$A$3:$G$100,6,FALSE)=0,"",VLOOKUP(D7,[1]List!$A$3:$G$100,6,FALSE)) | K7: =IF(VLOOKUP(D7,[1]List!$A$3:$G$100,7,FALSE)=0,"",VLOOKUP(D7,[1]List!$A$3:$G$100,7,FALSE))
A8: ​Genesee County (NY) Emergency Management Services:​Oakfield (NY) Fire Department (Genesee County) | B8: Customer 6 | D8: Dashboards:Dashboard - 2-Year Standard Subscription (deleted) | E8: Prod/Svc6 | F8: =IF(VLOOKUP(D8,[1]List!$A$3:$G$100,2,FALSE)=0,"",VLOOKUP(D8,[1]List!$A$3:$G$100,2,FALSE)) -> yes | G8: =IF(VLOOKUP(D8,[1]List!$A$3:$G$100,3,FALSE)=0,"",VLOOKUP(D8,[1]List!$A$3:$G$100,3,FALSE)) | H8: =IF(VLOOKUP(D8,[1]List!$A$3:$G$100,4,FALSE)=0,"",VLOOKUP(D8,[1]List!$A$3:$G$100,4,FALSE)) | I8: =IF(VLOOKUP(D8,[1]List!$A$3:$G$100,5,FALSE)=0,"",VLOOKUP(D8,[1]List!$A$3:$G$100,5,FALSE)) | J8: =IF(VLOOKUP(D8,[1]List!$A$3:$G$100,6,FALSE)=0,"",VLOOKUP(D8,[1]List!$A$3:$G$100,6,FALSE)) | K8: =IF(VLOOKUP(D8,[1]List!$A$3:$G$100,7,FALSE)=0,"",VLOOKUP(D8,[1]List!$A$3:$G$100,7,FALSE))
A9: ​Genesee County (NY) Emergency Management Services:Batavia (NY) Fire Department, ​City of (Genesee County) | B9: Customer 7 | D9: Dashboards:Dashboard - 3-Year Standard Subscription (deleted) | E9: Prod/Svc7 | F9: =IF(VLOOKUP(D9,[1]List!$A$3:$G$100,2,FALSE)=0,"",VLOOKUP(D9,[1]List!$A$3:$G$100,2,FALSE)) -> yes | G9: =IF(VLOOKUP(D9,[1]List!$A$3:$G$100,3,FALSE)=0,"",VLOOKUP(D9,[1]List!$A$3:$G$100,3,FALSE)) | H9: =IF(VLOOKUP(D9,[1]List!$A$3:$G$100,4,FALSE)=0,"",VLOOKUP(D9,[1]List!$A$3:$G$100,4,FALSE)) | I9: =IF(VLOOKUP(D9,[1]List!$A$3:$G$100,5,FALSE)=0,"",VLOOKUP(D9,[1]List!$A$3:$G$100,5,FALSE)) | J9: =IF(VLOOKUP(D9,[1]List!$A$3:$G$100,6,FALSE)=0,"",VLOOKUP(D9,[1]List!$A$3:$G$100,6,FALSE)) | K9: =IF(VLOOKUP(D9,[1]List!$A$3:$G$100,7,FALSE)=0,"",VLOOKUP(D9,[1]List!$A$3:$G$100,7,FALSE))
A10: ​Genesee County (NY) Emergency Management Services:Bethany (NY) Volunteer Fire Department (Genesee County) | B10: Customer 8 | D10: Dashboards:Dashboard - 4-Year Standard Subscription (deleted) | E10: Prod/Svc8 | F10: =IF(VLOOKUP(D10,[1]List!$A$3:$G$100,2,FALSE)=0,"",VLOOKUP(D10,[1]List!$A$3:$G$100,2,FALSE)) -> yes | G10: =IF(VLOOKUP(D10,[1]List!$A$3:$G$100,3,FALSE)=0,"",VLOOKUP(D10,[1]List!$A$3:$G$100,3,FALSE)) | H10: =IF(VLOOKUP(D10,[1]List!$A$3:$G$100,4,FALSE)=0,"",VLOOKUP(D10,[1]List!$A$3:$G$100,4,FALSE)) | I10: =IF(VLOOKUP(D10,[1]List!$A$3:$G$100,5,FALSE)=0,"",VLOOKUP(D10,[1]List!$A$3:$G$100,5,FALSE)) | J10: =IF(VLOOKUP(D10,[1]List!$A$3:$G$100,6,FALSE)=0,"",VLOOKUP(D10,[1]List!$A$3:$G$100,6,FALSE)) | K10: =IF(VLOOKUP(D10,[1]List!$A$3:$G$100,7,FALSE)=0,"",VLOOKUP(D10,[1]List!$A$3:$G$100,7,FALSE))
A11: ​Genesee County (NY) Emergency Management Services:Byron (NY) Fire Department (Genesee County) | B11: Customer 9 | D11: Dashboards:Dashboard - First Year New Basic License (deleted) | E11: Prod/Svc9 | F11: =IF(VLOOKUP(D11,[1]List!$A$3:$G$100,2,FALSE)=0,"",VLOOKUP(D11,[1]List!$A$3:$G$100,2,FALSE)) -> yes | G11: =IF(VLOOKUP(D11,[1]List!$A$3:$G$100,3,FALSE)=0,"",VLOOKUP(D11,[1]List!$A$3:$G$100,3,FALSE)) | H11: =IF(VLOOKUP(D11,[1]List!$A$3:$G$100,4,FALSE)=0,"",VLOOKUP(D11,[1]List!$A$3:$G$100,4,FALSE)) | I11: =IF(VLOOKUP(D11,[1]List!$A$3:$G$100,5,FALSE)=0,"",VLOOKUP(D11,[1]List!$A$3:$G$100,5,FALSE)) | J11: =IF(VLOOKUP(D11,[1]List!$A$3:$G$100,6,FALSE)=0,"",VLOOKUP(D11,[1]List!$A$3:$G$100,6,FALSE)) | K11: =IF(VLOOKUP(D11,[1]List!$A$3:$G$100,7,FALSE)=0,"",VLOOKUP(D11,[1]List!$A$3:$G$100,7,FALSE))
A12: ​Genesee County (NY) Emergency Management Services:Corfu (NY) Fire Department (Genesee County) | B12: Customer 10 | D12: Dashboards:Dashboard - First Year New Desktop/Tablet License (LEGACY) (deleted) | E12: Prod/Svc10 | F12: =IF(VLOOKUP(D12,[1]List!$A$3:$G$100,2,FALSE)=0,"",VLOOKUP(D12,[1]List!$A$3:$G$100,2,FALSE)) -> yes | G12: =IF(VLOOKUP(D12,[1]List!$A$3:$G$100,3,FALSE)=0,"",VLOOKUP(D12,[1]List!$A$3:$G$100,3,FALSE)) | H12: =IF(VLOOKUP(D12,[1]List!$A$3:$G$100,4,FALSE)=0,"",VLOOKUP(D12,[1]List!$A$3:$G$100,4,FALSE)) | I12: =IF(VLOOKUP(D12,[1]List!$A$3:$G$100,5,FALSE)=0,"",VLOOKUP(D12,[1]List!$A$3:$G$100,5,FALSE)) | J12: =IF(VLOOKUP(D12,[1]List!$A$3:$G$100,6,FALSE)=0,"",VLOOKUP(D12,[1]List!$A$3:$G$100,6,FALSE)) | K12: =IF(VLOOKUP(D12,[1]List!$A$3:$G$100,7,FALSE)=0,"",VLOOKUP(D12,[1]List!$A$3:$G$100,7,FALSE))
A13: ​Genesee County (NY) Emergency Management Services:Genesee County (NY) Emergency Management Services - Enterprise 2022 | B13: Customer 11 | D13: Dashboards:Dashboard - First Year New Standard License (LEGACY) (deleted) | E13: Prod/Svc11 | F13: =IF(VLOOKUP(D13,[1]List!$A$3:$G$100,2,FALSE)=0,"",VLOOKUP(D13,[1]List!$A$3:$G$100,2,FALSE)) -> yes | G13: =IF(VLOOKUP(D13,[1]List!$A$3:$G$100,3,FALSE)=0,"",VLOOKUP(D13,[1]List!$A$3:$G$100,3,FALSE)) | H13: =IF(VLOOKUP(D13,[1]List!$A$3:$G$100,4,FALSE)=0,"",VLOOKUP(D13,[1]List!$A$3:$G$100,4,FALSE)) | I13: =IF(VLOOKUP(D13,[1]List!$A$3:$G$100,5,FALSE)=0,"",VLOOKUP(D13,[1]List!$A$3:$G$100,5,FALSE)) | J13: =IF(VLOOKUP(D13,[1]List!$A$3:$G$100,6,FALSE)=0,"",VLOOKUP(D13,[1]List!$A$3:$G$100,6,FALSE)) | K13: =IF(VLOOKUP(D13,[1]List!$A$3:$G$100,7,FALSE)=0,"",VLOOKUP(D13,[1]List!$A$3:$G$100,7,FALSE))
A14: #1 Green Township (IN) Volunteer Fire Department | B14: Customer 12 | D14: Dashboards:Dashboard - Hardware (deleted) | E14: Prod/Svc12 | F14: =IF(VLOOKUP(D14,[1]List!$A$3:$G$100,2,FALSE)=0,"",VLOOKUP(D14,[1]List!$A$3:$G$100,2,FALSE)) -> yes | G14: =IF(VLOOKUP(D14,[1]List!$A$3:$G$100,3,FALSE)=0,"",VLOOKUP(D14,[1]List!$A$3:$G$100,3,FALSE)) | H14: =IF(VLOOKUP(D14,[1]List!$A$3:$G$100,4,FALSE)=0,"",VLOOKUP(D14,[1]List!$A$3:$G$100,4,FALSE)) | I14: =IF(VLOOKUP(D14,[1]List!$A$3:$G$100,5,FALSE)=0,"",VLOOKUP(D14,[1]List!$A$3:$G$100,5,FALSE)) | J14: =IF(VLOOKUP(D14,[1]List!$A$3:$G$100,6,FALSE)=0,"",VLOOKUP(D14,[1]List!$A$3:$G$100,6,FALSE)) | K14: =IF(VLOOKUP(D14,[1]List!$A$3:$G$100,7,FALSE)=0,"",VLOOKUP(D14,[1]List!$A$3:$G$100,7,FALSE))
A15: Abbeville County (SC) Emergency Services | B15: Customer 13 | D15: Dashboards:Dashboard - Hardware Device Deployment | E15: Prod/Svc13 | F15: =IF(VLOOKUP(D15,[1]List!$A$3:$G$100,2,FALSE)=0,"",VLOOKUP(D15,[1]List!$A$3:$G$100,2,FALSE)) | G15: =IF(VLOOKUP(D15,[1]List!$A$3:$G$100,3,FALSE)=0,"",VLOOKUP(D15,[1]List!$A$3:$G$100,3,FALSE)) | H15: =IF(VLOOKUP(D15,[1]List!$A$3:$G$100,4,FALSE)=0,"",VLOOKUP(D15,[1]List!$A$3:$G$100,4,FALSE)) -> yes | I15: =IF(VLOOKUP(D15,[1]List!$A$3:$G$100,5,FALSE)=0,"",VLOOKUP(D15,[1]List!$A$3:$G$100,5,FALSE)) | J15: =IF(VLOOKUP(D15,[1]List!$A$3:$G$100,6,FALSE)=0,"",VLOOKUP(D15,[1]List!$A$3:$G$100,6,FALSE)) | K15: =IF(VLOOKUP(D15,[1]List!$A$3:$G$100,7,FALSE)=0,"",VLOOKUP(D15,[1]List!$A$3:$G$100,7,FALSE))
... A86: Bloomington (IN) Fire Department | B86: Customer 84 | D86: Wilder KY FD - 1 Chromebox and License - 043020 (deleted) | E86: Prod/Svc84 | F86: =IF(VLOOKUP(D86,[1]List!$A$3:$G$100,2,FALSE)=0,"",VLOOKUP(D86,[1]List!$A$3:$G$100,2,FALSE)) -> yes | G86: =IF(VLOOKUP(D86,[1]List!$A$3:$G$100,3,FALSE)=0,"",VLOOKUP(D86,[1]List!$A$3:$G$100,3,FALSE)) | H86: =IF(VLOOKUP(D86,[1]List!$A$3:$G$100,4,FALSE)=0,"",VLOOKUP(D86,[1]List!$A$3:$G$100,4,FALSE)) | I86: =IF(VLOOKUP(D86,[1]List!$A$3:$G$100,5,FALSE)=0,"",VLOOKUP(D86,[1]List!$A$3:$G$100,5,FALSE)) | J86: =IF(VLOOKUP(D86,[1]List!$A$3:$G$100,6,FALSE)=0,"",VLOOKUP(D86,[1]List!$A$3:$G$100,6,FALSE)) | K86: =IF(VLOOKUP(D86,[1]List!$A$3:$G$100,7,FALSE)=0,"",VLOOKUP(D86,[1]List!$A$3:$G$100,7,FALSE))
A87: Blue Ridge (NC) Fire & Rescue | B87: Customer 85 | D87: 0
A88: Boca Raton (FL) Fire Rescue | B88: Customer 86
A89: Boca Raton (FL) Govt., City of | B89: Customer 87
A90: Bon Air (PA) Fire Company | B90: Customer 88
A91: Bonita Springs (FL) Fire Control and Rescue District | B91: Customer 89
A92: Bonner Springs (KS) Fire-EMS | B92: Customer 90
A93: Boone County (KY) Fire | B93: Customer 91
A94: Boonsboro (VA) Fire & Rescue | B94: Customer 92
A95: Boonton (NJ) Fire Department | B95: Customer 93
A96: Borough of Bellefonte (PA):Bellefonte (PA) Recruitment Project | B96: Customer 94
A97: Borough of Northvale (NJ) Fire Department | B97: Customer 95
A98: Borough of Northvale (NJ) Fire Department:Northvale (NJ) Fire Department-Standard Web Package-FY21-December | B98: Customer 96
A99: Botetourt County (VA) Fire & EMS | B99: Customer 97
... A993: Zionsville (IN) Fire Department | B993: Customer 991
B994: Customer 992
B995: Customer 993
B996: Customer 994

Sheet Sales by Cust Detail External
B2: Customer | C2: Date | D2: Transaction Type | E2: Num | F2: Product/Service | G2: Memo/Description | H2: Qty | I2: Sales Price | J2: Amount | K2: Subscription Start Date | L2: Subscription End Date
B3: =VLOOKUP('Sales by Customer Detail'!B6,Anonymizer!$A$3:$B$996,2,FALSE) -> Customer 564 | C3: ='Sales by Customer Detail'!C6 -> 01/02/2018 | D3: ='Sales by Customer Detail'!D6 -> Invoice | E3: ='Sales by Customer Detail'!E6 -> 1014 | F3: =VLOOKUP('Sales by Customer Detail'!F6,Anonymizer!$D$3:$E$86,2,FALSE) -> Prod/Svc70 | G3: memo | H3: ='Sales by Customer Detail'!J6 -> 1 | I3: ='Sales by Customer Detail'!K6 -> 30000 | J3: ='Sales by Customer Detail'!L6 -> 30000 | K3: ='Sales by Customer Detail'!N6 -> 0 | L3: ='Sales by Customer Detail'!O6 -> 0
B4: =VLOOKUP('Sales by Customer Detail'!B7,Anonymizer!$A$3:$B$996,2,FALSE) -> Customer 620 | C4: ='Sales by Customer Detail'!C7 -> 01/03/2018 | D4: ='Sales by Customer Detail'!D7 -> Invoice | E4: ='Sales by Customer Detail'!E7 -> 1016 | F4: =VLOOKUP('Sales by Customer Detail'!F7,Anonymizer!$D$3:$E$86,2,FALSE) -> Prod/Svc77 | G4: memo | H4: ='Sales by Customer Detail'!J7 -> 4 | I4: ='Sales by Customer Detail'!K7 -> 150 | J4: ='Sales by Customer Detail'!L7 -> 600 | K4: ='Sales by Customer Detail'!N7 -> 0 | L4: ='Sales by Customer Detail'!O7 -> 0
B5: =VLOOKUP('Sales by Customer Detail'!B8,Anonymizer!$A$3:$B$996,2,FALSE) -> Customer 35 | C5: ='Sales by Customer Detail'!C8 -> 01/03/2018 | D5: ='Sales by Customer Detail'!D8 -> Invoice | E5: ='Sales by Customer Detail'!E8 -> 1017 | F5: =VLOOKUP('Sales by Customer Detail'!F8,Anonymizer!$D$3:$E$86,2,FALSE) -> Prod/Svc77 | G5: memo | H5: ='Sales by Customer Detail'!J8 -> 1 | I5: ='Sales by Customer Detail'!K8 -> -35 | J5: ='Sales by Customer Detail'!L8 -> -35 | K5: ='Sales by Customer Detail'!N8 -> 0 | L5: ='Sales by Customer Detail'!O8 -> 0
B6: =VLOOKUP('Sales by Customer Detail'!B9,Anonymizer!$A$3:$B$996,2,FALSE) -> Customer 35 | C6: ='Sales by Customer Detail'!C9 -> 01/03/2018 | D6: ='Sales by Customer Detail'!D9 -> Invoice | E6: ='Sales by Customer Detail'!E9 -> 1017 | F6: =VLOOKUP('Sales by Customer Detail'!F9,Anonymizer!$D$3:$E$86,2,FALSE) -> Prod/Svc77 | G6: memo | H6: ='Sales by Customer Detail'!J9 -> 12 | I6: ='Sales by Customer Detail'!K9 -> 29 | J6: ='Sales by Customer Detail'!L9 -> 348 | K6: ='Sales by Customer Detail'!N9 -> 0 | L6: ='Sales by Customer Detail'!O9 -> 0
B7: =VLOOKUP('Sales by Customer Detail'!B10,Anonymizer!$A$3:$B$996,2,FALSE) -> Customer 328 | C7: ='Sales by Customer Detail'!C10 -> 01/03/2018 | D7: ='Sales by Customer Detail'!D10 -> Invoice | E7: ='Sales by Customer Detail'!E10 -> 1018 | F7: =VLOOKUP('Sales by Customer Detail'!F10,Anonymizer!$D$3:$E$86,2,FALSE) -> Prod/Svc77 | G7: memo | H7: ='Sales by Customer Detail'!J10 -> 12 | I7: ='Sales by Customer Detail'!K10 -> 49 | J7: ='Sales by Customer Detail'!L10 -> 588 | K7: ='Sales by Customer Detail'!N10 -> 0 | L7: ='Sales by Customer Detail'!O10 -> 0
B8: =VLOOKUP('Sales by Customer Detail'!B11,Anonymizer!$A$3:$B$996,2,FALSE) -> Customer 620 | C8: ='Sales by Customer Detail'!C11 -> 01/03/2018 | D8: ='Sales by Customer Detail'!D11 -> Invoice | E8: ='Sales by Customer Detail'!E11 -> 1016 | F8: =VLOOKUP('Sales by Customer Detail'!F11,Anonymizer!$D$3:$E$86,2,FALSE) -> Prod/Svc77 | G8: memo | H8: ='Sales by Customer Detail'!J11 -> 12 | I8: ='Sales by Customer Detail'!K11 -> 150 | J8: ='Sales by Customer Detail'!L11 -> 1800 | K8: ='Sales by Customer Detail'!N11 -> 0 | L8: ='Sales by Customer Detail'!O11 -> 0
B9: =VLOOKUP('Sales by Customer Detail'!B12,Anonymizer!$A$3:$B$996,2,FALSE) -> Customer 328 | C9: ='Sales by Customer Detail'!C12 -> 01/03/2018 | D9: ='Sales by Customer Detail'!D12 -> Invoice | E9: ='Sales by Customer Detail'!E12 -> 1018 | F9: =VLOOKUP('Sales by Customer Detail'!F12,Anonymizer!$D$3:$E$86,2,FALSE) -> Prod/Svc77 | G9: memo | H9: ='Sales by Customer Detail'!J12 -> 1 | I9: ='Sales by Customer Detail'!K12 -> -58.8 | J9: ='Sales by Customer Detail'!L12 -> -58.8 | K9: ='Sales by Customer Detail'!N12 -> 0 | L9: ='Sales by Customer Detail'!O12 -> 0
B10: =VLOOKUP('Sales by Customer Detail'!B13,Anonymizer!$A$3:$B$996,2,FALSE) -> Customer 620 | C10: ='Sales by Customer Detail'!C13 -> 01/03/2018 | D10: ='Sales by Customer Detail'!D13 -> Invoice | E10: ='Sales by Customer Detail'!E13 -> 1016 | F10: =VLOOKUP('Sales by Customer Detail'!F13,Anonymizer!$D$3:$E$86,2,FALSE) -> Prod/Svc77 | G10: memo | H10: ='Sales by Customer Detail'!J13 -> 1 | I10: ='Sales by Customer Detail'!K13 -> -240 | J10: ='Sales by Customer Detail'!L13 -> -240 | K10: ='Sales by Customer Detail'!N13 -> 0 | L10: ='Sales by Customer Detail'!O13 -> 0
B11: =VLOOKUP('Sales by Customer Detail'!B14,Anonymizer!$A$3:$B$996,2,FALSE) -> Customer 811 | C11: ='Sales by Customer Detail'!C14 -> 01/18/2018 | D11: ='Sales by Customer Detail'!D14 -> Invoice | E11: ='Sales by Customer Detail'!E14 -> 1019 | F11: =VLOOKUP('Sales by Customer Detail'!F14,Anonymizer!$D$3:$E$86,2,FALSE) -> Prod/Svc66 | G11: memo | H11: ='Sales by Customer Detail'!J14 -> 1 | I11: ='Sales by Customer Detail'!K14 -> 40000 | J11: ='Sales by Customer Detail'!L14 -> 40000 | K11: ='Sales by Customer Detail'!N14 -> 0 | L11: ='Sales by Customer Detail'!O14 -> 0
B12: =VLOOKUP('Sales by Customer Detail'!B15,Anonymizer!$A$3:$B$996,2,FALSE) -> Customer 67 | C12: ='Sales by Customer Detail'!C15 -> 01/31/2018 | D12: ='Sales by Customer Detail'!D15 -> Invoice | E12: ='Sales by Customer Detail'!E15 -> 1020 | F12: =VLOOKUP('Sales by Customer Detail'!F15,Anonymizer!$D$3:$E$86,2,FALSE) -> Prod/Svc77 | G12: memo | H12: ='Sales by Customer Detail'!J15 -> 24 | I12: ='Sales by Customer Detail'!K15 -> 59 | J12: ='Sales by Customer Detail'!L15 -> 1416 | K12: ='Sales by Customer Detail'!N15 -> 0 | L12: ='Sales by Customer Detail'!O15 -> 0
B13: =VLOOKUP('Sales by Customer Detail'!B16,Anonymizer!$A$3:$B$996,2,FALSE) -> Customer 67 | C13: ='Sales by Customer Detail'!C16 -> 01/31/2018 | D13: ='Sales by Customer Detail'!D16 -> Invoice | E13: ='Sales by Customer Detail'!E16 -> 1020 | F13: =VLOOKUP('Sales by Customer Detail'!F16,Anonymizer!$D$3:$E$86,2,FALSE) -> Prod/Svc73 | G13: memo | H13: ='Sales by Customer Detail'!J16 -> 1 | I13: ='Sales by Customer Detail'!K16 -> 3495 | J13: ='Sales by Customer Detail'!L16 -> 3495 | K13: ='Sales by Customer Detail'!N16 -> 0 | L13: ='Sales by Customer Detail'!O16 -> 0
B14: =VLOOKUP('Sales by Customer Detail'!B17,Anonymizer!$A$3:$B$996,2,FALSE) -> Customer 762 | C14: ='Sales by Customer Detail'!C17 -> 01/31/2018 | D14: ='Sales by Customer Detail'!D17 -> Invoice | E14: ='Sales by Customer Detail'!E17 -> 1021 | F14: =VLOOKUP('Sales by Customer Detail'!F17,Anonymizer!$D$3:$E$86,2,FALSE) -> Prod/Svc73 | G14: memo | H14: ='Sales by Customer Detail'!J17 -> 1 | I14: ='Sales by Customer Detail'!K17 -> 0 | J14: ='Sales by Customer Detail'!L17 -> 0 | K14: ='Sales by Customer Detail'!N17 -> 0 | L14: ='Sales by Customer Detail'!O17 -> 0
... B5758: =VLOOKUP('Sales by Customer Detail'!B5761,Anonymizer!$A$3:$B$996,2,FALSE) -> Customer 730 | C5758: ='Sales by Customer Detail'!C5761 -> 04/29/2022 | D5758: ='Sales by Customer Detail'!D5761 -> Invoice | E5758: ='Sales by Customer Detail'!E5761 -> 3969 | F5758: =VLOOKUP('Sales by Customer Detail'!F5761,Anonymizer!$D$3:$E$86,2,FALSE) -> Prod/Svc13 | G5758: memo | H5758: ='Sales by Customer Detail'!J5761 -> 1 | I5758: ='Sales by Customer Detail'!K5761 -> 299 | J5758: ='Sales by Customer Detail'!L5761 -> 299 | K5758: ='Sales by Customer Detail'!N5761 -> 05/20/2022 | L5758: ='Sales by Customer Detail'!O5761 -> 11/25/2022

Sheet ProdSvc mapping to revenue type
A1: Product/Service | B1: Dashboard Subscription | C1: Set Up | D1: Hardware | E1: Website Hosting / Support Subscription? | F1: Website Professional Services | G1: LLC Item
A2: Prod/Svc1 | B2: yes
A3: Prod/Svc2 | B3: yes
A4: Prod/Svc3 | G4: yes
A5: Prod/Svc4 | G5: yes
A6: Prod/Svc5 | C6: yes
A7: Prod/Svc6 | B7: yes
A8: Prod/Svc7 | B8: yes
A9: Prod/Svc8 | B9: yes
A10: Prod/Svc9 | B10: yes
A11: Prod/Svc10 | B11: yes
A12: Prod/Svc11 | B12: yes
A13: Prod/Svc12 | B13: yes
A14: Prod/Svc13 | D14: yes
A15: Prod/Svc14 | B15: yes
A16: Prod/Svc15 | C16: yes
A17: Prod/Svc16 | B17: yes
A18: Prod/Svc17 | C18: yes
A19: Prod/Svc18 | B19: yes
A20: Prod/Svc19 | B20: yes
A21: Prod/Svc20 | C21: yes
A22: Prod/Svc21 | B22: yes
A23: Prod/Svc22 | B23: yes
A24: Prod/Svc23 | C24: yes
A25: Prod/Svc24 | B25: yes
A26: Prod/Svc25 | B26: yes
A27: Prod/Svc26 | B27: yes
A28: Prod/Svc27 | B28: yes
A29: Prod/Svc28 | B29: yes
A30: Prod/Svc29 | B30: yes
A31: Prod/Svc30 | B31: yes
A32: Prod/Svc31 | B32: yes
A33: Prod/Svc32 | B33: yes
A34: Prod/Svc33 | B34: yes
A35: Prod/Svc34 | B35: yes
A36: Prod/Svc35 | B36: yes
... A38: Prod/Svc37 | B38: yes
A39: Prod/Svc38 | C39: yes
A40: Prod/Svc39 | B40: yes
A41: Prod/Svc40 | C41: yes
...

Sheet Rev rec assumptions
B3: Revenue recognition period assumptions
B5: Dashboard Subscription | C5: Recognize revenue from the subscription start date to the subscription end date. If no dates, recognize revenue for one year starting at the invoice date.
B6: Set Up | C6: Recognize revenue over three years from the invoice date
B7: Hardware | C7: Regognize all revenue on the invoice date
B8: Website Hosting / Support Subscription? | C8: Recognize revenue from the subscription start date to the subscription end date. If no dates, recognize revenue for one year starting at the invoice date.
B9: Website Professional Services | C9: Regognize all revenue on the invoice date
B10: LLC Item | C10: Regognize all revenue on the invoice date
